ogging exception.
Traceback (most recent call last):
  File "/home/runner/workspace/.pythonlibs/lib/python3.11/site-packages/telegram/ext/_application.py", line 1311, in process_update
    await coroutine
  File "/home/runner/workspace/.pythonlibs/lib/python3.11/site-packages/telegram/ext/_handlers/basehandler.py", line 158, in handle_update
    return await self.callback(update, context)
           ^^^^^^^^^^^^^^^^^^^^^^^^^^^^^^^^^^^^
  File "/home/runner/workspace/bot_manager.py", line 797, in _cmd_help
    await update.message.reply_text(help_text, parse_mode='Markdown')
  File "/home/runner/workspace/.pythonlibs/lib/python3.11/site-packages/telegram/_message.py", line 1910, in reply_text
    return await self.get_bot().send_message(
           ^^^^^^^^^^^^^^^^^^^^^^^^^^^^^^^^^^
  File "/home/runner/workspace/.pythonlibs/lib/python3.11/site-packages/telegram/ext/_extbot.py", line 3055, in send_message
    return await super().send_message(
           ^^^^^^^^^^^^^^^^^^^^^^^^^^^
  File "/home/runner/workspace/.pythonlibs/lib/python3.11/site-packages/telegram/_bot.py", line 1100, in send_message
    return await self._send_message(
           ^^^^^^^^^^^^^^^^^^^^^^^^^
  File "/home/runner/workspace/.pythonlibs/lib/python3.11/site-packages/telegram/ext/_extbot.py", line 630, in _send_message
    result = await super()._send_message(
             ^^^^^^^^^^^^^^^^^^^^^^^^^^^^
  File "/home/runner/workspace/.pythonlibs/lib/python3.11/site-packages/telegram/_bot.py", line 810, in _send_message
    result = await self._post(
             ^^^^^^^^^^^^^^^^^
  File "/home/runner/workspace/.pythonlibs/lib/python3.11/site-packages/telegram/_bot.py", line 698, in _post
    return await self._do_post(
           ^^^^^^^^^^^^^^^^^^^^
  File "/home/runner/workspace/.pythonlibs/lib/python3.11/site-packages/telegram/ext/_extbot.py", line 370, in _do_post
    return await super()._do_post(
           ^^^^^^^^^^^^^^^^^^^^^^^
  File "/home/runner/workspace/.pythonlibs/lib/python3.11/site-packages/telegram/_bot.py", line 727, in _do_post
    result = await request.post(
             ^^^^^^^^^^^^^^^^^^^
  File "/home/runner/workspace/.pythonlibs/lib/python3.11/site-packages/telegram/request/_baserequest.py", line 197, in post
    result = await self._request_wrapper(
             ^^^^^^^^^^^^^^^^^^^^^^^^^^^^
  File "/home/runner/workspace/.pythonlibs/lib/python3.11/site-packages/telegram/request/_baserequest.py", line 374, in _request_wrapper
    raise exception
telegram.error.BadRequest: Can't parse entities: can't find end of the entity starting at byte offset 1499
2025-07-24 11:52:08,283 - health_monitor - ERROR - CRITICAL: System health critical - 1 alerts
2025-07-24 11:52:08,283 - health_monitor - ERROR - CRITICAL: Error Rate is 28.75589999999999%
2025-07-24 11:52:08,312 - health_monitor - CRITICAL - System in critical state - taking protective actions
2025-07-24 11:52:09,810 - httpx - INFO - HTTP Request: POST https://api.telegram.org/bot7763869226:AAHEWmD_xF3weTiIpOMfphg9iFvWALm_FyM/getUpdates "HTTP/1.1 200 OK"
2025-07-24 11:52:10,508 - httpx - INFO - HTTP Request: POST https://api.telegram.org/bot7626841974:AAEBhQ4Cia9aTUz7zEHheVKh9O0Fqu_7JqA/getMe "HTTP/1.1 200 OK"
2025-07-24 11:52:10,509 - bot_manager - INFO - Metrics - Processed: 7, Success Rate: 0.71, Queue: 0
2025-07-24 11:52:14,276 - httpx - INFO - HTTP Request: POST https://api.telegram.org/bot7763869226:AAHEWmD_xF3weTiIpOMfphg9iFvWALm_FyM/getUpdates "HTTP/1.1 200 OK"
2025-07-24 11:52:14,835 - httpx - INFO - HTTP Request: POST https://api.telegram.org/bot7763869226:AAHEWmD_xF3weTiIpOMfphg9iFvWALm_FyM/sendMessage "HTTP/1.1 400 Bad Request"
2025-07-24 11:52:14,836 - telegram.ext.Application - ERROR - No error handlers are registered, logging exception.
Traceback (most recent call last):
  File "/home/runner/workspace/.pythonlibs/lib/python3.11/site-packages/telegram/ext/_application.py", line 1311, in process_update
    await coroutine
  File "/home/runner/workspace/.pythonlibs/lib/python3.11/site-packages/telegram/ext/_handlers/basehandler.py", line 158, in handle_update
    return await self.callback(update, context)
           ^^^^^^^^^^^^^^^^^^^^^^^^^^^^^^^^^^^^
  File "/home/runner/workspace/bot_manager.py", line 797, in _cmd_help
    await update.message.reply_text(help_text, parse_mode='Markdown')
  File "/home/runner/workspace/.pythonlibs/lib/python3.11/site-packages/telegram/_message.py", line 1910, in reply_text
    return await self.get_bot().send_message(
           ^^^^^^^^^^^^^^^^^^^^^^^^^^^^^^^^^^
  File "/home/runner/workspace/.pythonlibs/lib/python3.11/site-packages/telegram/ext/_extbot.py", line 3055, in send_message
    return await super().send_message(
           ^^^^^^^^^^^^^^^^^^^^^^^^^^^
  File "/home/runner/workspace/.pythonlibs/lib/python3.11/site-packages/telegram/_bot.py", line 1100, in send_message
    return await self._send_message(
           ^^^^^^^^^^^^^^^^^^^^^^^^^
  File "/home/runner/workspace/.pythonlibs/lib/python3.11/site-packages/telegram/ext/_extbot.py", line 630, in _send_message
    result = await super()._send_message(
             ^^^^^^^^^^^^^^^^^^^^^^^^^^^^
  File "/home/runner/workspace/.pythonlibs/lib/python3.11/site-packages/telegram/_bot.py", line 810, in _send_message
    result = await self._post(
             ^^^^^^^^^^^^^^^^^
  File "/home/runner/workspace/.pythonlibs/lib/python3.11/site-packages/telegram/_bot.py", line 698, in _post
    return await self._do_post(
           ^^^^^^^^^^^^^^^^^^^^
  File "/home/runner/workspace/.pythonlibs/lib/python3.11/site-packages/telegram/ext/_extbot.py", line 370, in _do_post
    return await super()._do_post(
           ^^^^^^^^^^^^^^^^^^^^^^^
  File "/home/runner/workspace/.pythonlibs/lib/python3.11/site-packages/telegram/_bot.py", line 727, in _do_post
    result = await request.post(
             ^^^^^^^^^^^^^^^^^^^
  File "/home/runner/workspace/.pythonlibs/lib/python3.11/site-packages/telegram/request/_baserequest.py", line 197, in post
    result = await self._request_wrapper(
             ^^^^^^^^^^^^^^^^^^^^^^^^^^^^
  File "/home/runner/workspace/.pythonlibs/lib/python3.11/site-packages/telegram/request/_baserequest.py", line 374, in _request_wrapper
    raise exception
telegram.error.BadRequest: Can't parse entities: can't find end of the entity starting at byte offset 1499